Workbook

Sheet 00 Start Here
B1: Attention Is All You Need — A Teaching Workbook
B2: Vaswani, Shazeer, Parmar, Uszkoreit, Jones, Gomez, Kaiser & Polosukhin (2017). NeurIPS 2017. arXiv:1706.03762 (v7). This workbook explains the paper for a newcomer, one concept per sheet.
B4: BIG IDEA: In 2017 this paper replaced the step-by-step reading of sentences with a mechanism called attention, letting every word look at every other word at once. That design — the Transformer — is the foundation of today's large language models.
B5: How each sheet is organised
B6: • BIG IDEA — the concept in one or two sentences.
B7: • Plain-English explanation and an ANALOGY from everyday life.
B8: • The paper's FORMULA, then a table reading it symbol by symbol, with the paper's actual values.
B9: • EXAMPLE 1 (simplest) — tiny numbers you could check with a pencil, every step expanded.
B10: • EXAMPLE 2+ (moderate) — larger or more realistic cases, often reproducing a number printed in the paper.
B11: • CHECK YOURSELF — short questions with answers.
B12: Colour legend
B13: 1.5 | C13: Input — blue on yellow. Type over it; everything downstream recalculates.
B14: =B13*2 -> 3 | C14: Formula — black. Never typed in by hand; always computed.
B15: =B13 -> 1.5 | C15: Link — green. Pulled live from another sheet (the running example flows between sheets).
B16: =B13*3 -> 4.5 | C16: Key result — bold on green.
B17: Show the work | C17: Grey rows rebuild the arithmetic as live text, e.g. '1×2 + 0×1 = 2', so you can follow every step.
B19: The running example: one sentence through a whole encoder layer
B20: The English sentence 'the cat sat' is carried through the sheets using a tiny model (d_model = 4 numbers per word instead of 512): its tokens are looked up (03), given positions (04), turned into queries/keys/values (05), attended over (06, 08), added and normalised (10), and passed through the feed-forward network (11). Change a word on sheet 03 (e.g. 'sat' → 'cat') and watch every downstream number update.
B21: Contents (click a sheet name)
B22: Sheet | E22: What you'll learn | L22: Paper section | N22: Level
B23: 01 Math Toolkit | E23: Vectors, dot products, matrices, softmax, mean/variance, ReLU, log | L23: prerequisite | N23: ★☆☆
B24: 02 Big Picture | E24: The translation task, RNN limits, the Transformer's one big idea, Figure 1 | L24: Abstract, §1–3 | N24: ★☆☆
B25: 03 Embeddings | E25: Tokens (BPE), embedding lookup, ×√d_model, shared weights | L25: §3.4, §5.1 | N25: ★☆☆
B26: 04 Positional Enc | E26: Sine/cosine position stamps; why shifts are rotations | L26: §3.5 | N26: ★★☆
B27: 05 Query-Key-Value | E27: Attention as a soft dictionary lookup; X·W_Q, X·W_K, X·W_V | L27: §3.2 | N27: ★☆☆
B28: 06 Scaled Attention | E28: Equation (1) step by step; why divide by √d_k | L28: §3.2.1 | N28: ★★☆
B29: 07 Masking | E29: Hiding future words in the decoder; teacher forcing | L29: §3.1, §3.2.3 | N29: ★★☆
B30: 08 Multi-Head | E30: h parallel heads, concat, W_O; Table 3 rows A/B | L30: §3.2.2 | N30: ★★☆
B31: 09 Three Attentions | E31: Encoder self-, masked decoder self-, and cross-attention | L31: §3.2.3 | N31: ★☆☆
B32: 10 Add and Norm | E32: Residual connections and layer normalisation | L32: §3.1 | N32: ★★☆
B33: 11 Feed-Forward | E33: Equation (2); completes a full encoder layer by formula | L33: §3.3 | N33: ★★☆
... B42: 20 Glossary | E42: Every symbol and term | L42: — | N42: —
B43: Suggested learning path
B44: • Complete beginner: 01 → 02 → 05 → 06 → 08 → 04 → 03 → 09, then the rest in order.
B45: • Comfortable with basic linear algebra: 02 → 03 → 04 → 05 → 06 → 07 → 08 → 10 → 11 → 12 → 17.
B46: • Interested in training and results: 13 → 14 → 15 → 16 → 18 → 19.
B47: The paper in one paragraph
B48: Each input word becomes a vector (embedding) with a position pattern added. In the encoder, six identical layers each let every word gather information from every other word (multi-head self-attention) and then process it individually (feed-forward), with residual connections and layer normalisation around both. The decoder does the same over the words written so far — masked so it can't see the future — plus a cross-attention step that looks at the encoded input. A final softmax over the vocabulary predicts the next word. Trained with Adam, a warm-up learning-rate schedule, dropout and label smoothing, the model beat all previous translation systems at a fraction of their training cost.
B49: NOTE: All example numbers (embeddings, weights, probabilities) are small made-up values chosen to be readable, unless a row says 'Source: the paper'. Values quoted from the paper are cited to their section or table.

Sheet 01 Math Toolkit
B1: 01 · The Math Toolkit — every piece of math the paper uses, from zero
B2: Prerequisite sheet. Nothing here is new research; it is the vocabulary the paper assumes you already speak.
B4: BIG IDEA: The whole Transformer is built from only a handful of operations: multiply-and-add (dot products), tables of numbers (matrices), turning scores into percentages (softmax), and a few averages. Master these ten small tools and every equation in the paper becomes readable.
B5: How to read the colours in every sheet: BLUE numbers on a yellow background are inputs — type over them. BLACK numbers are live formulas. GREEN numbers are pulled from another sheet. Green-shaded bold cells are the key results. The grey 'Show the work' lines rebuild the arithmetic as text, so you can check it by hand.
B7: Tool 1 · A vector is just a list of numbers that describes something
B8: Imagine describing fruit to a friend who can't see it, using only two scores out of 10: how SWEET it is and how CRUNCHY it is. A mango might be [9, 1] and a carrot [2, 9]. That list is a vector. Each position has a fixed meaning (position 1 = sweetness, position 2 = crunchiness).
B9: In the paper every word (token) is described by a list of d_model = 512 numbers. Nobody decides what each of the 512 positions means — the model learns it — but the idea is the same as our fruit scores.
B10: Simplest example — fruit as 2-number vectors
C11: sweet | D11: crunchy
B12: mango | C12: 9 | D12: 1
B13: carrot | C13: 2 | D13: 9
B14: apple | C14: 6 | D14: 7
B16: Tool 2 · The dot product — 'how much do two vectors agree?'
B17: a · b = a₁×b₁ + a₂×b₂ + … + aₙ×bₙ
B18: Multiply the numbers position by position, then add everything up. The answer is ONE number. It is large and positive when the two lists are high in the same places (they 'agree'), near zero when they are unrelated, and negative when they disagree. Attention is built on this single idea: a word asks 'how well do I match you?' by taking a dot product.
B19: Example 1 (simplest): a = [1, 2], b = [3, 4]
B20: Vector a | E20: Vector b
C21: pos 1 | D21: pos 2 | F21: pos 1 | G21: pos 2
C22: 1 | D22: 2 | F22: 3 | G22: 4
B24: a₁ × b₁ | C24: =C22*F22 -> 3 | D24: first pair multiplied
B25: a₂ × b₂ | C25: =D22*G22 -> 8 | D25: second pair multiplied
B26: a · b | C26: =C24+C25 -> 11 | D26: add the products
B27: Show the work | C27: ="a·b = "&IF(ROUND(C22,3)<0,"("&ROUND(C22,3)&")",ROUND(C22,3)&"")&"×"&IF(ROUND(F22,3)<0,"("&ROUND(F22,3)&")",ROUND(F22,3)&"")&" + "&IF(ROUND(D22,3)<0,"("&ROUND(D22,3)&")",ROUND(D22,3)&"")&"×"&IF(ROUND(G22,3)<0,"("&ROUND(G22,3)&")",ROUND(G22,3)&"")&" = "&IF(ROUND(C26,3)<0,"("&ROUND(C26,3)&")",ROUND(C26,3)&"") -> a·b = 1×3 + 2×4 = 11
B29: Example 2 (moderate): are 'king' and 'queen' more alike than 'king' and 'apple'?
B30: Below are made-up 4-number word vectors (features could loosely be: royalty, person-ness, food-ness, femaleness). The raw dot product grows with the SIZE of vectors, so we also compute COSINE SIMILARITY = dot ÷ (length of a × length of b), which ignores size and ranges from −1 (opposite) to +1 (same direction). Length = √(sum of squares).
B31: Word vectors (illustrative)
C32: royal | D32: person | E32: food | F32: female
B33: king | C33: 0.9 | D33: 0.8 | E33: 0.1 | F33: 0.1
B34: queen | C34: 0.85 | D34: 0.75 | E34: 0.1 | F34: 0.9
B35: apple | C35: 0 | D35: 0.1 | E35: 0.95 | F35: 0.2
B37: Pair | C37: Dot product | E37: Length of 1st | G37: Length of 2nd | I37: Cosine similarity | K37: Reading
B38: king · queen | C38: =C33*C34+D33*D34+E33*E34+F33*F34 -> 1.465 | E38: =SQRT(SUMSQ(C33:F33)) -> 1.2124356 | G38: =SQRT(SUMSQ(C34:F34)) -> 1.4508618 | I38: =C38/(E38*G38) -> 0.83282338 | K38: =IF(C33*C34+D33*D34+E33*E34+F33*F34/(SQRT(SUMSQ(C33:F33))*SQRT(SUMSQ(C34:F34)))>0.5,"similar","not similar") -> similar
B39: king · apple | C39: =C33*C35+D33*D35+E33*E35+F33*F35 -> 0.195 | E39: =SQRT(SUMSQ(C33:F33)) -> 1.2124356 | G39: =SQRT(SUMSQ(C35:F35)) -> 0.97596106 | I39: =C39/(E39*G39) -> 0.16479478 | K39: =IF(C33*C35+D33*D35+E33*E35+F33*F35/(SQRT(SUMSQ(C33:F33))*SQRT(SUMSQ(C35:F35)))>0.5,"similar","not similar") -> not similar
B40: queen · apple | C40: =C34*C35+D34*D35+E34*E35+F34*F35 -> 0.35 | E40: =SQRT(SUMSQ(C34:F34)) -> 1.4508618 | G40: =SQRT(SUMSQ(C35:F35)) -> 0.97596106 | I40: =C40/(E40*G40) -> 0.24717782 | K40: =IF(C34*C35+D34*D35+E34*E35+F34*F35/(SQRT(SUMSQ(C34:F34))*SQRT(SUMSQ(C35:F35)))>0.5,"similar","not similar") -> not similar
B41: Show the work | C41: ="king·queen = "&IF(ROUND(C33,3)<0,"("&ROUND(C33,3)&")",ROUND(C33,3)&"")&"×"&IF(ROUND(C34,3)<0,"("&ROUND(C34,3)&")",ROUND(C34,3)&"")&" + "&IF(ROUND(D33,3)<0,"("&ROUND(D33,3)&")",ROUND(D33,3)&"")&"×"&IF(ROUND(D34,3)<0,"("&ROUND(D34,3)&")",ROUND(D34,3)&"")&" + "&IF(ROUND(E33,3)<0,"("&ROUND(E33,3)&")",ROUND(E33,3)&"")&"×"&IF(ROUND(E34,3)<0,"("&ROUND(E34,3)&")",ROUND(E34,3)&"")&" + "&IF(ROUND(F33,3)<0,"("&ROUND(F33,3)&")",ROUND(F33,3)&"")&"×"&IF(ROUND(F34,3)<0,"("&ROUND(F34,3)&")",ROUND(F34,3)&"")&" = "&IF(ROUND(C38,3)<0,"("&ROUND(C38,3)&")",ROUND(C38,3)&"") -> king·queen = 0.9×0.85 + 0.8×0.75 + 0.1×0.1 + 0.1×0.9 = 1.465
B43: Tool 3 · A matrix is a table of vectors; the transpose flips it
B44: Stack several vectors as rows and you get a matrix. In the paper, a sentence of n words becomes a matrix with n rows (one per word) and 512 columns (one per feature). The TRANSPOSE (written with a superscript T, e.g. Kᵀ) swaps rows and columns: row 1 becomes column 1. The paper needs Kᵀ so that every word's query can be multiplied against every word's key in one go.
B45: Matrix K (2 rows × 3 columns) | G45: Kᵀ (3 × 2) — live formulas
C46: col 1 | D46: col 2 | E46: col 3 | H46: from row 1 | I46: from row 2
B47: row 1 | C47: 1 | D47: 2 | E47: 3 | G47: col 1→row | H47: =C47 -> 1 | I47: =C48 -> 4
...

Sheet 02 Big Picture
B1: 02 · The Big Picture — what problem the paper solves, and its one bold idea
B2: Paper: Abstract, §1 Introduction, §2 Background, §3 (encoder–decoder), Figure 1
B4: BIG IDEA: Before 2017, translation models read a sentence one word at a time, like passing a note down a line of people. The Transformer lets every word look at every other word directly and all at the same time, using only 'attention'. No recurrence, no convolution.
B5: 1. The task: sequence transduction (e.g. translation)
B6: 'Transduction' just means turning one sequence into another: English sentence → German sentence. The paper tests on WMT 2014 English→German (4.5 million sentence pairs) and English→French (36 million sentences).
B7: The standard design is an ENCODER–DECODER. The encoder reads the whole input and produces a rich numeric summary of each input word, z = (z₁…zₙ). The decoder then writes the output ONE word at a time, each time looking at (i) what it has written so far and (ii) the encoder's summary. Writing one word at a time while feeding your own previous words back in is called AUTO-REGRESSIVE generation.
B8: ANALOGY: A human interpreter first listens to the whole English sentence (encoder), then speaks the German translation word by word, glancing back at their notes and at what they have already said (decoder).
B9: 2. The old way (RNNs) and its two problems
B10: Recurrent network: hₜ = f( hₜ₋₁ , xₜ )
B11: A recurrent neural network (RNN, LSTM, GRU) keeps a 'memory' vector hₜ and updates it word by word: the memory after word t depends on the memory after word t−1. The paper names two problems with this:
B12: • NO PARALLELISM: you can't compute step 5 until step 4 is done. GPUs are great at doing thousands of things at once, so a strictly sequential chain wastes them. (§1: 'This inherently sequential nature precludes parallelization within training examples.')
B13: • LONG PATHS: information from word 1 must survive every intermediate update to influence word 50. The longer the path, the harder it is to learn such long-range links (§4 calls this 'maximum path length').
... B17: Example 1 (simplest): a 3-word sentence 'the cat sat'
B18: Words in sentence (n) | C18: 3 | D18: change this number and watch the table update
B19: Quantity | G19: RNN | I19: Self-attention | K19: Why
B20: Sequential steps to process the sentence | G20: =C18 -> 3 | I20: =1 -> 1 | K20: RNN must go word by word; attention handles all words at once
B21: Steps for word 1 to influence word n | G21: =C18-1 -> 2 | I21: =1 -> 1 | K21: RNN passes the message along; attention connects directly
B22: Number of word-pair connections made per layer | G22: =C18-1 -> 2 | I22: =C18^2 -> 9 | K22: attention compares every word with every word (n × n) — the price we pay
B24: Example 2 (moderate): a toy 'telephone game' — how fast does a signal fade over distance?
B25: ILLUSTRATION (not from the paper): suppose each hop through an RNN keeps only a fraction of the useful signal. For attention the distance is always one hop. Change the 'kept per hop' input to explore.
B26: Signal kept per hop | C26: 0.9 | D26: assumption for illustration only
B27: Distance between two words | E27: Signal left via RNN (keep^distance) | H27: Signal left via attention | K27: Reading
B28: 1 | E28: =C26^B28 -> 0.9 | H28: =C26 -> 0.9 | K28: =IF(E28<0.01,"RNN signal essentially lost",IF(E28<0.5,"RNN signal badly faded","RNN still OK")) -> RNN still OK
B29: 5 | E29: =C26^B29 -> 0.59049 | H29: =C26 -> 0.9 | K29: =IF(E29<0.01,"RNN signal essentially lost",IF(E29<0.5,"RNN signal badly faded","RNN still OK")) -> RNN still OK
B30: 10 | E30: =C26^B30 -> 0.34867844 | H30: =C26 -> 0.9 | K30: =IF(E30<0.01,"RNN signal essentially lost",IF(E30<0.5,"RNN signal badly faded","RNN still OK")) -> RNN signal badly faded
B31: 20 | E31: =C26^B31 -> 0.12157665 | H31: =C26 -> 0.9 | K31: =IF(E31<0.01,"RNN signal essentially lost",IF(E31<0.5,"RNN signal badly faded","RNN still OK")) -> RNN signal badly faded
B32: 50 | E32: =C26^B32 -> 0.0051537752 | H32: =C26 -> 0.9 | K32: =IF(E32<0.01,"RNN signal essentially lost",IF(E32<0.5,"RNN signal badly faded","RNN still OK")) -> RNN signal essentially lost
B33: 100 | E33: =C26^B33 -> 2.6561399e-05 | H33: =C26 -> 0.9 | K33: =IF(E33<0.01,"RNN signal essentially lost",IF(E33<0.5,"RNN signal badly faded","RNN still OK")) -> RNN signal essentially lost
B35: 4. The architecture in one picture (Figure 1, redrawn as a list)
B36: Read top to bottom. The left column (encoder) runs once over the whole input. The right column (decoder) runs once per output word. 'N×' means the block is stacked N = 6 times.
C37: ENCODER | I37: DECODER
C38: Input words: 'the cat sat' | I38: Output so far (shifted right): '<s> Die Katze'
C39: Input Embedding (sheet 03) | I39: Output Embedding (shared, sheet 03)
C40: + Positional Encoding (sheet 04) | I40: + Positional Encoding (sheet 04)
C41: ┌ N× encoder layer ┐ | I41: ┌ N× decoder layer ┐
C42: Multi-Head Self-Attention (06, 08) | I42: MASKED Multi-Head Self-Attention (07)
C43: Add & Norm (sheet 10) | I43: Add & Norm
C44: Feed-Forward (sheet 11) | I44: Encoder–Decoder Attention (sheet 09)
C45: Add & Norm (sheet 10) | I45: Add & Norm
C46: └──────────┘ | I46: Feed-Forward, Add & Norm
...

Sheet 03 Embeddings
B1: 03 · Tokens & Embeddings — turning words into numbers
B2: Paper: §3.4 Embeddings and Softmax, §5.1 Training Data (byte-pair encoding, 37,000-token shared vocabulary)
B4: BIG IDEA: A neural network can only do arithmetic, so each word is replaced by a learned list of numbers (its embedding). Words used in similar ways end up with similar lists.
B5: 1. Tokens: the pieces a sentence is cut into
B6: The paper does not use whole words. It uses BYTE-PAIR ENCODING (BPE), which splits text into frequent sub-word pieces. Common words stay whole ('the'), rare words are split ('unbelievably' → 'un' + 'believ' + 'ably'). This keeps the vocabulary to a fixed size — about 37,000 tokens shared between English and German — while still being able to spell any word. For English–French they used a similar 32,000 'word-piece' vocabulary.
B7: Word | E7: Possible BPE tokens (illustrative) | J7: Why
B8: the | E8: the | J8: very common → kept whole
B9: cats | E9: cat + s | J9: stem + common ending
B10: unbelievably | E10: un + believ + ably | J10: rare word → built from frequent pieces
B11: Katze (German) | E11: Katze | J11: shared vocabulary holds both languages
B13: 2. Embeddings: a lookup table with one row per token
B14: The model keeps a big table: one ROW per token in the vocabulary, d_model = 512 COLUMNS. To embed a sentence you simply look up each token's row. The numbers start random and are LEARNED during training, so tokens that behave alike drift close together.
B15: embedding(token) = row of the table for that token, then multiplied by √d_model
B16: Symbol | C16: What it means in plain English | L16: Value in the paper
B17: vocabulary size | C17: How many different tokens exist (rows in the table) | L17: ≈ 37,000 (EN–DE)
B18: d_model | C18: Length of every token's vector (columns in the table) | L18: 512 (base), 1024 (big)
B19: √d_model | C19: Scale factor applied to embeddings (§3.4: 'we multiply those weights by √d_model') | L19: √512 ≈ 22.6
B20: Example 1 (simplest): a tiny 8-token shared vocabulary with d_model = 4
B21: Below is our whole 'vocabulary'. It holds English AND German tokens, just like the paper's shared BPE vocabulary. The numbers are made up, but deliberately 'cat' and 'Katze' are similar, 'the' ≈ 'die', 'sat' ≈ 'saß' — the kind of structure training produces. These rows are reused by sheets 04–12.
B22: Embedding table E (8 tokens × d_model 4)
C23: dim 1 | D23: dim 2 | E23: dim 3 | F23: dim 4
B24: <s> | C24: 0.1 | D24: -0.1 | E24: 0 | F24: 0.2
B25: </s> | C25: -0.1 | D25: 0.1 | E25: 0.2 | F25: 0
B26: the | C26: 0.5 | D26: -0.2 | E26: 0.1 | F26: 0
B27: cat | C27: -0.3 | D27: 0.8 | E27: 0.4 | F27: -0.1
B28: sat | C28: 0.2 | D28: 0.1 | E28: -0.6 | F28: 0.5
B29: die | C29: 0.4 | D29: -0.3 | E29: 0.2 | F29: 0.1
B30: Katze | C30: -0.2 | D30: 0.7 | E30: 0.5 | F30: -0.2
B31: saß | C31: 0.3 | D31: 0 | E31: -0.5 | F31: 0.6
B33: d_model | C33: 4 | D33: vector length in this toy example (the paper uses 512)
B34: Sentence to embed — type any vocabulary tokens into the three yellow cells (e.g. 'the', 'cat', 'sat'):
B35: Token | C35: Row # in table (MATCH)
B36: the | C36: =MATCH(B36,$B$24:$B$31,0) -> 3
B37: cat | C37: =MATCH(B37,$B$24:$B$31,0) -> 4
B38: sat | C38: =MATCH(B38,$B$24:$B$31,0) -> 5
B40: Step 1 — look up each token's row (INDEX) | H40: Step 2 — multiply by √d_model
C41: dim 1 | D41: dim 2 | E41: dim 3 | F41: dim 4 | I41: dim 1 | J41: dim 2 | K41: dim 3 | L41: dim 4
B42: =B36 -> the | C42: =INDEX($C$24:$F$31,C36,1) -> 0.5 | D42: =INDEX($C$24:$F$31,C36,2) -> -0.2 | E42: =INDEX($C$24:$F$31,C36,3) -> 0.1 | F42: =INDEX($C$24:$F$31,C36,4) -> 0 | H42: =B36 -> the | I42: =C42*SQRT(C33) -> 1 | J42: =D42*SQRT(C33) -> -0.4 | K42: =E42*SQRT(C33) -> 0.2 | L42: =F42*SQRT(C33) -> 0
B43: =B37 -> cat | C43: =INDEX($C$24:$F$31,C37,1) -> -0.3 | D43: =INDEX($C$24:$F$31,C37,2) -> 0.8 | E43: =INDEX($C$24:$F$31,C37,3) -> 0.4 | F43: =INDEX($C$24:$F$31,C37,4) -> -0.1 | H43: =B37 -> cat | I43: =C43*SQRT(C33) -> -0.6 | J43: =D43*SQRT(C33) -> 1.6 | K43: =E43*SQRT(C33) -> 0.8 | L43: =F43*SQRT(C33) -> -0.2
B44: =B38 -> sat | C44: =INDEX($C$24:$F$31,C38,1) -> 0.2 | D44: =INDEX($C$24:$F$31,C38,2) -> 0.1 | E44: =INDEX($C$24:$F$31,C38,3) -> -0.6 | F44: =INDEX($C$24:$F$31,C38,4) -> 0.5 | H44: =B38 -> sat | I44: =C44*SQRT(C33) -> 0.4 | J44: =D44*SQRT(C33) -> 0.2 | K44: =E44*SQRT(C33) -> -1.2 | L44: =F44*SQRT(C33) -> 1
...

Sheet 04 Positional Enc
B1: 04 · Positional Encoding — telling the model the ORDER of words
B2: Paper: §3.5 Positional Encoding; Table 3 row (E)
B4: BIG IDEA: Attention treats a sentence like a bag of words — 'dog bites man' and 'man bites dog' look identical. So the paper ADDS a unique wave pattern to each position's vector, like stamping each word with a timestamp.
B5: 1. Why it's needed
B6: Self-attention computes a weighted blend where the weights depend only on WHAT the words are, not WHERE they are. Shuffle the words and each word gets exactly the same result (just in shuffled order). RNNs knew order for free because they read left to right; the Transformer does not, so order must be injected.
B7: ANALOGY: A clock. The second hand spins fast, the minute hand slower, the hour hand slowest. Reading all hands together tells you the exact time. Each pair of dimensions in the positional encoding is one 'hand', rotating at its own speed as you move along the sentence.
B8: 2. The formula
B9: PE(pos, 2i) = sin( pos / 10000^(2i / d_model) ) PE(pos, 2i+1) = cos( pos / 10000^(2i / d_model) )
B10: Symbol | C10: What it means in plain English | L10: Value in the paper
B11: pos | C11: Position of the word in the sentence: 0, 1, 2, … | L11: any
B12: i | C12: Index of the sin/cos PAIR: dimensions (0,1) are pair i=0, (2,3) are i=1, … | L12: 0 … 255
B13: 2i, 2i+1 | C13: Even dimensions use sin, odd dimensions use cos | L13: —
B14: 10000^(2i/d_model) | C14: How slowly this pair rotates. i=0 → divide by 1 (fast); last pair → divide by ~10000 (slow) | L14: —
B15: wavelength | C15: Distance (in positions) for one full cycle = 2π × 10000^(2i/d_model): from 2π up to about 10000·2π | L15: 2π … ≈10000·2π
B16: Once computed, the positional encoding is simply ADDED to the (scaled) word embedding: input = √d_model·E[token] + PE[pos]. Same length (d_model), so they can be summed element by element.
B17: Example 1 (simplest): d_model = 4, positions 0 to 5 — every step expanded
B18: With d_model = 4 there are 2 pairs: i = 0 (dims 1–2) rotates at speed 1; i = 1 (dims 3–4) rotates 100× slower because 10000^(2/4) = 100.
B19: d_model | C19: 4 | D19: change to 6 or 8 and the frequencies below update
B20: Base constant | C20: 10000 | D20: the paper's 10000
B21: Divisor for pair i=0 | C21: =C20^(2*0/C19) -> 1 | D21: 10000^(0/d_model) = 1
B22: Divisor for pair i=1 | C22: =C20^(2*1/C19) -> 100 | D22: 10000^(2/d_model) = 100 when d_model = 4
B23: pos | C23: angle₀ = pos/div₀ | D23: dim1 = sin(angle₀) | E23: dim2 = cos(angle₀) | F23: angle₁ = pos/div₁ | G23: dim3 = sin(angle₁) | H23: dim4 = cos(angle₁)
B24: 0 | C24: =B24/C21 -> 0 | D24: =SIN(C24) -> 0 | E24: =COS(C24) -> 1 | F24: =B24/C22 -> 0 | G24: =SIN(F24) -> 0 | H24: =COS(F24) -> 1
B25: 1 | C25: =B25/C21 -> 1 | D25: =SIN(C25) -> 0.84147098 | E25: =COS(C25) -> 0.54030231 | F25: =B25/C22 -> 0.01 | G25: =SIN(F25) -> 0.0099998333 | H25: =COS(F25) -> 0.99995
B26: 2 | C26: =B26/C21 -> 2 | D26: =SIN(C26) -> 0.90929743 | E26: =COS(C26) -> -0.41614684 | F26: =B26/C22 -> 0.02 | G26: =SIN(F26) -> 0.019998667 | H26: =COS(F26) -> 0.99980001
B27: 3 | C27: =B27/C21 -> 3 | D27: =SIN(C27) -> 0.14112001 | E27: =COS(C27) -> -0.9899925 | F27: =B27/C22 -> 0.03 | G27: =SIN(F27) -> 0.0299955 | H27: =COS(F27) -> 0.99955003
B28: 4 | C28: =B28/C21 -> 4 | D28: =SIN(C28) -> -0.7568025 | E28: =COS(C28) -> -0.65364362 | F28: =B28/C22 -> 0.04 | G28: =SIN(F28) -> 0.039989334 | H28: =COS(F28) -> 0.99920011
B29: 5 | C29: =B29/C21 -> 5 | D29: =SIN(C29) -> -0.95892427 | E29: =COS(C29) -> 0.28366219 | F29: =B29/C22 -> 0.05 | G29: =SIN(F29) -> 0.049979169 | H29: =COS(F29) -> 0.99875026
B31: pos 2, dim 1 | C31: ="sin( "&B26&" / "&IF(ROUND(C21,3)<0,"("&ROUND(C21,3)&")",ROUND(C21,3)&"")&" ) = sin("&IF(ROUND(C26,3)<0,"("&ROUND(C26,3)&")",ROUND(C26,3)&"")&" radians) = "&IF(ROUND(D26,3)<0,"("&ROUND(D26,3)&")",ROUND(D26,3)&"") -> sin( 2 / 1 ) = sin(2 radians) = 0.909
B32: pos 2, dim 3 | C32: ="sin( "&B26&" / "&IF(ROUND(C22,3)<0,"("&ROUND(C22,3)&")",ROUND(C22,3)&"")&" ) = sin("&IF(ROUND(F26,3)<0,"("&ROUND(F26,3)&")",ROUND(F26,3)&"")&" radians) = "&IF(ROUND(G26,3)<0,"("&ROUND(G26,3)&")",ROUND(G26,3)&"") -> sin( 2 / 100 ) = sin(0.02 radians) = 0.02
B33: Look down the columns: dims 1–2 swing quickly through positive and negative values (the 'second hand'); dims 3–4 barely move over 6 positions (the 'hour hand'). Every row is a different combination — a unique fingerprint for that position.
B35: Example 2 (moderate): adding position to the words 'the cat sat' → the real encoder input X
B36: This is the exact input the encoder's first layer sees. It takes the scaled embeddings from sheet 03 (green) and adds the positional encodings for positions 0, 1, 2 from the table above. This X feeds sheets 05 → 06 → 08 → 10 → 11.
B37: √d·E[token] (from sheet 03) | G37: PE[pos 0,1,2]
C38: dim 1 | D38: dim 2 | E38: dim 3 | F38: dim 4 | H38: dim 1 | I38: dim 2 | J38: dim 3 | K38: dim 4
B39: ='03 Embeddings'!$B$36 -> the | C39: ='03 Embeddings'!$I$42 -> 1 | D39: ='03 Embeddings'!$J$42 -> -0.4 | E39: ='03 Embeddings'!$K$42 -> 0.2 | F39: ='03 Embeddings'!$L$42 -> 0 | G39: pos 0 | H39: =D24 -> 0 | I39: =E24 -> 1 | J39: =G24 -> 0 | K39: =H24 -> 1
B40: ='03 Embeddings'!$B$37 -> cat | C40: ='03 Embeddings'!$I$43 -> -0.6 | D40: ='03 Embeddings'!$J$43 -> 1.6 | E40: ='03 Embeddings'!$K$43 -> 0.8 | F40: ='03 Embeddings'!$L$43 -> -0.2 | G40: pos 1 | H40: =D25 -> 0.84147098 | I40: =E25 -> 0.54030231 | J40: =G25 -> 0.0099998333 | K40: =H25 -> 0.99995
B41: ='03 Embeddings'!$B$38 -> sat | C41: ='03 Embeddings'!$I$44 -> 0.4 | D41: ='03 Embeddings'!$J$44 -> 0.2 | E41: ='03 Embeddings'!$K$44 -> -1.2 | F41: ='03 Embeddings'!$L$44 -> 1 | G41: pos 2 | H41: =D26 -> 0.90929743 | I41: =E26 -> -0.41614684 | J41: =G26 -> 0.019998667 | K41: =H26 -> 0.99980001
B43: X = √d·E + PE (encoder input)
C44: dim 1 | D44: dim 2 | E44: dim 3 | F44: dim 4
...

Sheet 05 Query-Key-Value
B1: 05 · Queries, Keys and Values — attention as a 'soft' dictionary lookup
B2: Paper: §3.2 Attention ('mapping a query and a set of key-value pairs to an output'), §3.2.2 projections W_Q, W_K, W_V
B4: BIG IDEA: Attention is a search. Each word sends out a QUERY ('what am I looking for?'), every word advertises a KEY ('what do I contain?'), and each word also carries a VALUE ('what I will hand over if you pick me'). The answer is a blend of values, weighted by how well each key matches the query.
B5: §3.2 in the paper's words: 'An attention function can be described as mapping a query and a set of key-value pairs to an output… The output is computed as a weighted sum of the values, where the weight assigned to each value is computed by a compatibility function of the query with the corresponding key.'
B6: ANALOGY: A library. Your QUERY is the question in your head. Each book's KEY is the label on its spine. Its VALUE is the content inside. A normal dictionary returns exactly one book (hard lookup). Attention reads a little from every book, more from the ones whose labels match your question best (soft lookup).
B7: Example 1 (simplest): a fruit shop with 3 items
B8: Keys describe each fruit with 2 numbers [sweet, crunchy]. Values are the prices. Our query says 'I want SWEET' = [1, 0]. (No √d_k scaling yet — that arrives on sheet 06.)
B9: Query q ('sweet, please')
C10: sweet | D10: crunchy
C11: 1 | D11: 0
B13: Keys K | F13: Values V (price)
C14: sweet | D14: crunchy | G14: price
B15: mango | C15: 2 | D15: 0 | F15: mango | G15: 30
B16: carrot | C16: 0 | D16: 2 | F16: carrot | G16: 10
B17: apple | C17: 1 | D17: 1 | F17: apple | G17: 20
B19: Step 1 | C19: Score = how well the query matches each key = dot product q · kᵢ.
B20: Scores
C21: q · k
B22: mango | C22: =C11*C15+D11*D15 -> 2
B23: carrot | C23: =C11*C16+D11*D16 -> 0
B24: apple | C24: =C11*C17+D11*D17 -> 1
B26: mango | C26: ="q·k_mango = "&IF(ROUND(C11,3)<0,"("&ROUND(C11,3)&")",ROUND(C11,3)&"")&"×"&IF(ROUND(C15,3)<0,"("&ROUND(C15,3)&")",ROUND(C15,3)&"")&" + "&IF(ROUND(D11,3)<0,"("&ROUND(D11,3)&")",ROUND(D11,3)&"")&"×"&IF(ROUND(D15,3)<0,"("&ROUND(D15,3)&")",ROUND(D15,3)&"")&" = "&IF(ROUND(C22,3)<0,"("&ROUND(C22,3)&")",ROUND(C22,3)&"") -> q·k_mango = 1×2 + 0×0 = 2
B27: carrot | C27: ="q·k_carrot = "&IF(ROUND(C11,3)<0,"("&ROUND(C11,3)&")",ROUND(C11,3)&"")&"×"&IF(ROUND(C16,3)<0,"("&ROUND(C16,3)&")",ROUND(C16,3)&"")&" + "&IF(ROUND(D11,3)<0,"("&ROUND(D11,3)&")",ROUND(D11,3)&"")&"×"&IF(ROUND(D16,3)<0,"("&ROUND(D16,3)&")",ROUND(D16,3)&"")&" = "&IF(ROUND(C23,3)<0,"("&ROUND(C23,3)&")",ROUND(C23,3)&"") -> q·k_carrot = 1×0 + 0×2 = 0
B28: apple | C28: ="q·k_apple = "&IF(ROUND(C11,3)<0,"("&ROUND(C11,3)&")",ROUND(C11,3)&"")&"×"&IF(ROUND(C17,3)<0,"("&ROUND(C17,3)&")",ROUND(C17,3)&"")&" + "&IF(ROUND(D11,3)<0,"("&ROUND(D11,3)&")",ROUND(D11,3)&"")&"×"&IF(ROUND(D17,3)<0,"("&ROUND(D17,3)&")",ROUND(D17,3)&"")&" = "&IF(ROUND(C24,3)<0,"("&ROUND(C24,3)&")",ROUND(C24,3)&"") -> q·k_apple = 1×1 + 0×1 = 1
B29: Step 2 | C29: Softmax turns the scores into attention weights that add up to 1.
B30: e^score
C31: e^s
B32: mango | C32: =EXP(C22) -> 7.3890561
B33: carrot | C33: =EXP(C23) -> 1
B34: apple | C34: =EXP(C24) -> 2.7182818
B36: total | C36: =SUM(C32:C34) -> 11.107338
B37: Weights
C38: weight
B39: mango | C39: =C32/C36 -> 0.66524096
B40: carrot | C40: =C33/C36 -> 0.090030573
B41: apple | C41: =C34/C36 -> 0.24472847
B43: Step 3 | C43: Output = weighted sum of the values = Σ weightᵢ × valueᵢ.
B44: Soft answer | C44: =C39*G15+C40*G16+C41*G17 -> 25.752104 | D44: a blend: mostly mango's price, a bit of apple's, a little carrot's
B45: Show the work | C45: ="output = "&IF(ROUND(C39,3)<0,"("&ROUND(C39,3)&")",ROUND(C39,3)&"")&"×"&IF(ROUND(G15,3)<0,"("&ROUND(G15,3)&")",ROUND(G15,3)&"")&" + "&IF(ROUND(C40,3)<0,"("&ROUND(C40,3)&")",ROUND(C40,3)&"")&"×"&IF(ROUND(G16,3)<0,"("&ROUND(G16,3)&")",ROUND(G16,3)&"")&" + "&IF(ROUND(C41,3)<0,"("&ROUND(C41,3)&")",ROUND(C41,3)&"")&"×"&IF(ROUND(G17,3)<0,"("&ROUND(G17,3)&")",ROUND(G17,3)&"")&" = "&IF(ROUND(C44,3)<0,"("&ROUND(C44,3)&")",ROUND(C44,3)&"") -> output = 0.665×30 + 0.09×10 + 0.245×20 = 25.752
B46: Hard lookup | C46: =INDEX(G15:G17,MATCH(MAX(C22:C24),C22:C24,0)) -> 30 | D46: an ordinary dictionary would return ONLY the best match's value
...

Sheet 06 Scaled Attention
B1: 06 · Scaled Dot-Product Attention — the paper's Equation (1)
B2: Paper: §3.2.1, Equation (1), Figure 2 (left), footnote 4
B4: Attention(Q, K, V) = softmax( Q · Kᵀ / √d_k ) · V
B5: BIG IDEA: Four moves: (1) score every query against every key with a dot product, (2) shrink the scores by √d_k, (3) softmax each row into weights, (4) blend the values with those weights.
B6: Symbol | C6: What it means in plain English | L6: Value in the paper
B7: Q | C7: Queries — one row per word that is 'asking' | L7: n × d_k
B8: K | C8: Keys — one row per word being 'asked about' | L8: n × d_k
B9: Kᵀ | C9: K transposed, so Q·Kᵀ gives an n × n table of every query-key dot product | L9: d_k × n
B10: √d_k | C10: Square root of the key length; the scaling factor | L10: √64 = 8
B11: softmax(…) | C11: Applied to each ROW separately: each word's weights sum to 1 | L11: —
B12: V | C12: Values — what gets blended | L12: n × d_v
B13: Step | C13: Operation | F13: Shape (paper sizes) | I13: Plain meaning
B14: 1 | C14: S = Q · Kᵀ | F14: n × n | I14: how much each word matches each other word
B15: 2 | C15: S ÷ √d_k | F15: n × n | I15: tame the size of the scores
B16: 3 | C16: A = softmax(rows) | F16: n × n | I16: attention weights; each row sums to 1
B17: 4 | C17: Output = A · V | F17: n × d_v | I17: each word's new vector = weighted blend of values
B19: Example 1 (simplest): 3 words, d_k = 2, Q/K/V given directly
B20: Q | F20: K | J20: V
C21: d1 | D21: d2 | G21: d1 | H21: d2 | K21: d1 | L21: d2
B22: I | C22: 1 | D22: 0 | F22: I | G22: 2 | H22: 0 | J22: I | K22: 1 | L22: 0
B23: love | C23: 1 | D23: 1 | F23: love | G23: 0 | H23: 1 | J23: love | K23: 0 | L23: 1
B24: pizza | C24: 0 | D24: 2 | F24: pizza | G24: 1 | H24: 1 | J24: pizza | K24: 1 | L24: 1
B26: d_k | C26: 2 | D26: length of each query/key vector
B27: Step 1 | C27: Scores S = Q·Kᵀ. Row = the word asking, column = the word being looked at.
B28: S = Q · Kᵀ
C29: I | D29: love | E29: pizza
B30: I | C30: =C22*G22+D22*H22 -> 2 | D30: =C22*G23+D22*H23 -> 0 | E30: =C22*G24+D22*H24 -> 1
B31: love | C31: =C23*G22+D23*H22 -> 2 | D31: =C23*G23+D23*H23 -> 1 | E31: =C23*G24+D23*H24 -> 2
B32: pizza | C32: =C24*G22+D24*H22 -> 0 | D32: =C24*G23+D24*H23 -> 2 | E32: =C24*G24+D24*H24 -> 2
B34: S[I→I] | C34: =IF(ROUND(C22,3)<0,"("&ROUND(C22,3)&")",ROUND(C22,3)&"")&"×"&IF(ROUND(G22,3)<0,"("&ROUND(G22,3)&")",ROUND(G22,3)&"")&" + "&IF(ROUND(D22,3)<0,"("&ROUND(D22,3)&")",ROUND(D22,3)&"")&"×"&IF(ROUND(H22,3)<0,"("&ROUND(H22,3)&")",ROUND(H22,3)&"")&" = "&IF(ROUND(C30,3)<0,"("&ROUND(C30,3)&")",ROUND(C30,3)&"") -> 1×2 + 0×0 = 2
B35: S[I→love] | C35: =IF(ROUND(C22,3)<0,"("&ROUND(C22,3)&")",ROUND(C22,3)&"")&"×"&IF(ROUND(G23,3)<0,"("&ROUND(G23,3)&")",ROUND(G23,3)&"")&" + "&IF(ROUND(D22,3)<0,"("&ROUND(D22,3)&")",ROUND(D22,3)&"")&"×"&IF(ROUND(H23,3)<0,"("&ROUND(H23,3)&")",ROUND(H23,3)&"")&" = "&IF(ROUND(D30,3)<0,"("&ROUND(D30,3)&")",ROUND(D30,3)&"") -> 1×0 + 0×1 = 0
B36: S[I→pizza] | C36: =IF(ROUND(C22,3)<0,"("&ROUND(C22,3)&")",ROUND(C22,3)&"")&"×"&IF(ROUND(G24,3)<0,"("&ROUND(G24,3)&")",ROUND(G24,3)&"")&" + "&IF(ROUND(D22,3)<0,"("&ROUND(D22,3)&")",ROUND(D22,3)&"")&"×"&IF(ROUND(H24,3)<0,"("&ROUND(H24,3)&")",ROUND(H24,3)&"")&" = "&IF(ROUND(E30,3)<0,"("&ROUND(E30,3)&")",ROUND(E30,3)&"") -> 1×1 + 0×1 = 1
B37: S[love→I] | C37: =IF(ROUND(C23,3)<0,"("&ROUND(C23,3)&")",ROUND(C23,3)&"")&"×"&IF(ROUND(G22,3)<0,"("&ROUND(G22,3)&")",ROUND(G22,3)&"")&" + "&IF(ROUND(D23,3)<0,"("&ROUND(D23,3)&")",ROUND(D23,3)&"")&"×"&IF(ROUND(H22,3)<0,"("&ROUND(H22,3)&")",ROUND(H22,3)&"")&" = "&IF(ROUND(C31,3)<0,"("&ROUND(C31,3)&")",ROUND(C31,3)&"") -> 1×2 + 1×0 = 2
B38: S[love→love] | C38: =IF(ROUND(C23,3)<0,"("&ROUND(C23,3)&")",ROUND(C23,3)&"")&"×"&IF(ROUND(G23,3)<0,"("&ROUND(G23,3)&")",ROUND(G23,3)&"")&" + "&IF(ROUND(D23,3)<0,"("&ROUND(D23,3)&")",ROUND(D23,3)&"")&"×"&IF(ROUND(H23,3)<0,"("&ROUND(H23,3)&")",ROUND(H23,3)&"")&" = "&IF(ROUND(D31,3)<0,"("&ROUND(D31,3)&")",ROUND(D31,3)&"") -> 1×0 + 1×1 = 1
B39: S[love→pizza] | C39: =IF(ROUND(C23,3)<0,"("&ROUND(C23,3)&")",ROUND(C23,3)&"")&"×"&IF(ROUND(G24,3)<0,"("&ROUND(G24,3)&")",ROUND(G24,3)&"")&" + "&IF(ROUND(D23,3)<0,"("&ROUND(D23,3)&")",ROUND(D23,3)&"")&"×"&IF(ROUND(H24,3)<0,"("&ROUND(H24,3)&")",ROUND(H24,3)&"")&" = "&IF(ROUND(E31,3)<0,"("&ROUND(E31,3)&")",ROUND(E31,3)&"") -> 1×1 + 1×1 = 2
B40: S[pizza→I] | C40: =IF(ROUND(C24,3)<0,"("&ROUND(C24,3)&")",ROUND(C24,3)&"")&"×"&IF(ROUND(G22,3)<0,"("&ROUND(G22,3)&")",ROUND(G22,3)&"")&" + "&IF(ROUND(D24,3)<0,"("&ROUND(D24,3)&")",ROUND(D24,3)&"")&"×"&IF(ROUND(H22,3)<0,"("&ROUND(H22,3)&")",ROUND(H22,3)&"")&" = "&IF(ROUND(C32,3)<0,"("&ROUND(C32,3)&")",ROUND(C32,3)&"") -> 0×2 + 2×0 = 0
B41: S[pizza→love] | C41: =IF(ROUND(C24,3)<0,"("&ROUND(C24,3)&")",ROUND(C24,3)&"")&"×"&IF(ROUND(G23,3)<0,"("&ROUND(G23,3)&")",ROUND(G23,3)&"")&" + "&IF(ROUND(D24,3)<0,"("&ROUND(D24,3)&")",ROUND(D24,3)&"")&"×"&IF(ROUND(H23,3)<0,"("&ROUND(H23,3)&")",ROUND(H23,3)&"")&" = "&IF(ROUND(D32,3)<0,"("&ROUND(D32,3)&")",ROUND(D32,3)&"") -> 0×0 + 2×1 = 2
B42: S[pizza→pizza] | C42: =IF(ROUND(C24,3)<0,"("&ROUND(C24,3)&")",ROUND(C24,3)&"")&"×"&IF(ROUND(G24,3)<0,"("&ROUND(G24,3)&")",ROUND(G24,3)&"")&" + "&IF(ROUND(D24,3)<0,"("&ROUND(D24,3)&")",ROUND(D24,3)&"")&"×"&IF(ROUND(H24,3)<0,"("&ROUND(H24,3)&")",ROUND(H24,3)&"")&" = "&IF(ROUND(E32,3)<0,"("&ROUND(E32,3)&")",ROUND(E32,3)&"") -> 0×1 + 2×1 = 2
B43: Step 2 | C43: Divide every score by √d_k = √2 ≈ 1.414.
B44: S ÷ √d_k
...

Sheet 07 Masking
B1: 07 · Masking — stopping the decoder from peeking at future words
B2: Paper: §3.1 (Decoder), §3.2.3 third bullet, Figure 2 ('Mask (opt.)')
B4: BIG IDEA: During training the decoder is shown the whole correct translation at once (fast!), but each position must predict its next word WITHOUT seeing it. A mask sets the scores for 'future' words to −∞, so softmax gives them exactly 0 weight.
B5: ANALOGY: A student working through an answer sheet with a piece of card covering every line below the one they're on. They may read everything above; nothing below.
B6: 1. Shifted right: what each decoder position sees and predicts
B7: §3.1: the output embeddings are 'offset by one position', and masking ensures 'the predictions for position i can depend only on the known outputs at positions less than i'. For the target 'Die Katze saß':
B8: Position | C8: Decoder INPUT at this position | G8: Allowed to look at | K8: Must PREDICT
B9: 1 | C9: <s> (start token) | G9: <s> | K9: Die
B10: 2 | C10: Die | G10: <s>, Die | K10: Katze
B11: 3 | C11: Katze | G11: <s>, Die, Katze | K11: saß
B12: 4 | C12: saß | G12: <s>, Die, Katze, saß | K12: </s> (end)
B13: This is called 'teacher forcing': all four predictions are trained in parallel in one pass, which is a big part of why the Transformer trains fast. At translation time (inference) the decoder really does go one word at a time.
B14: masked score[i, j] = score[i, j] if j ≤ i, −∞ if j > i then softmax as usual
B16: Example 1 (simplest): 3 × 3 scores, apply the mask, softmax
B17: Raw scores (given) | G17: Mask (0 = allowed)
C18: <s> | D18: Die | E18: Katze | H18: <s> | I18: Die | J18: Katze
B19: <s> | C19: 2 | D19: 1 | E19: 3 | G19: <s> | H19: =IF(0>0,-1000000000,0) -> 0 | I19: =IF(1>0,-1000000000,0) -> -1000000000 | J19: =IF(2>0,-1000000000,0) -> -1000000000
B20: Die | C20: 1 | D20: 2 | E20: 0 | G20: Die | H20: =IF(0>1,-1000000000,0) -> 0 | I20: =IF(1>1,-1000000000,0) -> 0 | J20: =IF(2>1,-1000000000,0) -> -1000000000
B21: Katze | C21: 0 | D21: 1 | E21: 2 | G21: Katze | H21: =IF(0>2,-1000000000,0) -> 0 | I21: =IF(1>2,-1000000000,0) -> 0 | J21: =IF(2>2,-1000000000,0) -> 0
B23: In Excel we use −1,000,000,000 for −∞ (displayed as −∞). e^(−1,000,000,000) is 0 to every decimal place.
B24: Masked scores = S + mask
C25: <s> | D25: Die | E25: Katze
B26: <s> | C26: =C19+H19 -> 2 | D26: =D19+I19 -> -999999999 | E26: =E19+J19 -> -999999997
B27: Die | C27: =C20+H20 -> 1 | D27: =D20+I20 -> 2 | E27: =E20+J20 -> -1000000000
B28: Katze | C28: =C21+H21 -> 0 | D28: =D21+I21 -> 1 | E28: =E21+J21 -> 2
B30: exp(score) | H30: Masked attention weights
C31: <s> | D31: Die | E31: Katze | F31: row total | I31: <s> | J31: Die | K31: Katze
B32: <s> | C32: =EXP(C26) -> 7.3890561 | D32: =EXP(D26) -> 0 | E32: =EXP(E26) -> 0 | F32: =SUM(C32:E32) -> 7.3890561 | H32: <s> | I32: =C32/F32 -> 1 | J32: =D32/F32 -> 0 | K32: =E32/F32 -> 0
B33: Die | C33: =EXP(C27) -> 2.7182818 | D33: =EXP(D27) -> 7.3890561 | E33: =EXP(E27) -> 0 | F33: =SUM(C33:E33) -> 10.107338 | H33: Die | I33: =C33/F33 -> 0.26894142 | J33: =D33/F33 -> 0.73105858 | K33: =E33/F33 -> 0
B34: Katze | C34: =EXP(C28) -> 1 | D34: =EXP(D28) -> 2.7182818 | E34: =EXP(E28) -> 7.3890561 | F34: =SUM(C34:E34) -> 11.107338 | H34: Katze | I34: =C34/F34 -> 0.090030573 | J34: =D34/F34 -> 0.24472847 | K34: =E34/F34 -> 0.66524096
B36: Row <s> | C36: ="only itself allowed: "&IF(ROUND(C32,3)<0,"("&ROUND(C32,3)&")",ROUND(C32,3)&"")&" ÷ "&IF(ROUND(F32,3)<0,"("&ROUND(F32,3)&")",ROUND(F32,3)&"")&" = "&IF(ROUND(I32,3)<0,"("&ROUND(I32,3)&")",ROUND(I32,3)&"")&" (future words get 0)" -> only itself allowed: 7.389 ÷ 7.389 = 1 (future words get 0)
B37: Row Die | C37: ="e^"&IF(ROUND(C27,3)<0,"("&ROUND(C27,3)&")",ROUND(C27,3)&"")&" and e^"&IF(ROUND(D27,3)<0,"("&ROUND(D27,3)&")",ROUND(D27,3)&"")&" → "&IF(ROUND(C33,3)<0,"("&ROUND(C33,3)&")",ROUND(C33,3)&"")&", "&IF(ROUND(D33,3)<0,"("&ROUND(D33,3)&")",ROUND(D33,3)&"")&"; ÷ "&IF(ROUND(F33,3)<0,"("&ROUND(F33,3)&")",ROUND(F33,3)&"")&" → "&IF(ROUND(I33,3)<0,"("&ROUND(I33,3)&")",ROUND(I33,3)&"")&", "&IF(ROUND(J33,3)<0,"("&ROUND(J33,3)&")",ROUND(J33,3)&"")&", 0" -> e^1 and e^2 → 2.718, 7.389; ÷ 10.107 → 0.269, 0.731, 0
B38: The weight matrix is 'lower-triangular': everything above the diagonal is exactly 0. Notice the raw score for <s>→Katze was the biggest (3), yet it gets zero weight — the mask wins.
B40: Example 2 (moderate): full masked attention for '<s> Die Katze saß' (d_k = 2)
B41: Q | F41: K | J41: V
C42: d1 | D42: d2 | G42: d1 | H42: d2 | K42: d1 | L42: d2
B43: <s> | C43: 1 | D43: 0 | F43: <s> | G43: 1 | H43: 1 | J43: <s> | K43: 1 | L43: 0
B44: Die | C44: 0 | D44: 1 | F44: Die | G44: 1 | H44: 0 | J44: Die | K44: 0 | L44: 1
B45: Katze | C45: 1 | D45: 1 | F45: Katze | G45: 0 | H45: 2 | J45: Katze | K45: 2 | L45: 2
B46: saß | C46: 2 | D46: 0 | F46: saß | G46: 1 | H46: -1 | J46: saß | K46: 5 | L46: -5
...

Sheet 08 Multi-Head
B1: 08 · Multi-Head Attention — several attentions in parallel, each with its own 'lens'
B2: Paper: §3.2.2, Figure 2 (right), Table 3 rows (A) and (B)
B4: MultiHead(Q, K, V) = Concat(head₁, …, head_h) · W_O, where headᵢ = Attention(Q·W_Qᵢ, K·W_Kᵢ, V·W_Vᵢ)
B5: BIG IDEA: One attention can only produce one blend per word — it has to average everything it cares about. With h heads, each head projects the words into its own smaller space and attends independently (one might track grammar, another meaning, another the neighbouring word). The results are glued side by side and mixed by W_O.
B6: ANALOGY: A panel of 8 specialists reading the same sentence: a grammarian, a detective tracking who-did-what, a poet listening for tone… Each writes a short note; the notes are stapled together and an editor (W_O) combines them into one report.
B7: Symbol | C7: What it means in plain English | L7: Value in the paper
B8: h | C8: Number of heads | L8: 8 (base), 16 (big)
B9: d_k = d_v | C9: Size of each head's queries/keys/values = d_model / h | L9: 512 / 8 = 64
B10: W_Qᵢ, W_Kᵢ | C10: Head i's own projection matrices | L10: 512 × 64 each
B11: W_Vᵢ | C11: Head i's value projection | L11: 512 × 64
B12: Concat | C12: Place the h outputs side by side: h × d_v columns | L12: 8 × 64 = 512
B13: W_O | C13: Final mixing matrix | L13: 512 × 512
B14: Key point from the paper: 'Due to the reduced dimension of each head, the total computational cost is similar to that of single-head attention with full dimensionality.' 8 heads × 64 dims costs about the same as 1 head × 512.
B16: Example 1 (simplest possible real case): 'the cat sat', d_model = 4, h = 2 heads, d_k = d_v = 2
B17: X is live from sheet 04. Each head gets its own 4 × 2 weight matrices (here: head 1 uses the first two columns of sheet 05's matrices, head 2 the last two). Everything else is exactly sheet 06's recipe, done twice.
B18: X (from sheet 04)
C19: dim 1 | D19: dim 2 | E19: dim 3 | F19: dim 4
B20: ='03 Embeddings'!$B$36 -> the | C20: ='04 Positional Enc'!$C$45 -> 1 | D20: ='04 Positional Enc'!$D$45 -> 0.6 | E20: ='04 Positional Enc'!$E$45 -> 0.2 | F20: ='04 Positional Enc'!$F$45 -> 1
B21: ='03 Embeddings'!$B$37 -> cat | C21: ='04 Positional Enc'!$C$46 -> 0.24147098 | D21: ='04 Positional Enc'!$D$46 -> 2.1403023 | E21: ='04 Positional Enc'!$E$46 -> 0.80999983 | F21: ='04 Positional Enc'!$F$46 -> 0.79995
B22: ='03 Embeddings'!$B$38 -> sat | C22: ='04 Positional Enc'!$C$47 -> 1.3092974 | D22: ='04 Positional Enc'!$D$47 -> -0.21614684 | E22: ='04 Positional Enc'!$E$47 -> -1.1800013 | F22: ='04 Positional Enc'!$F$47 -> 1.9998
B24: d_k per head | C24: 2 | D24: d_model / h = 4 / 2
B25: Head 1
B26: W_Q1 (4×2) | F26: W_K1 (4×2) | J26: W_V1 (4×2)
C27: a | D27: b | G27: a | H27: b | K27: a | L27: b
B28: dim 1 | C28: ='05 Query-Key-Value'!$C$68 -> 1 | D28: ='05 Query-Key-Value'!$D$68 -> 0 | F28: dim 1 | G28: ='05 Query-Key-Value'!$I$68 -> 1 | H28: ='05 Query-Key-Value'!$J$68 -> 0 | J28: dim 1 | K28: ='05 Query-Key-Value'!$C$75 -> 0.5 | L28: ='05 Query-Key-Value'!$D$75 -> 0
B29: dim 2 | C29: ='05 Query-Key-Value'!$C$69 -> 0 | D29: ='05 Query-Key-Value'!$D$69 -> 1 | F29: dim 2 | G29: ='05 Query-Key-Value'!$I$69 -> 0 | H29: ='05 Query-Key-Value'!$J$69 -> 1 | J29: dim 2 | K29: ='05 Query-Key-Value'!$C$76 -> 0 | L29: ='05 Query-Key-Value'!$D$76 -> 1
B30: dim 3 | C30: ='05 Query-Key-Value'!$C$70 -> 1 | D30: ='05 Query-Key-Value'!$D$70 -> 0 | F30: dim 3 | G30: ='05 Query-Key-Value'!$I$70 -> 0 | H30: ='05 Query-Key-Value'!$J$70 -> 1 | J30: dim 3 | K30: ='05 Query-Key-Value'!$C$77 -> 0 | L30: ='05 Query-Key-Value'!$D$77 -> 0
B31: dim 4 | C31: ='05 Query-Key-Value'!$C$71 -> 0 | D31: ='05 Query-Key-Value'!$D$71 -> -1 | F31: dim 4 | G31: ='05 Query-Key-Value'!$I$71 -> 1 | H31: ='05 Query-Key-Value'!$J$71 -> 0 | J31: dim 4 | K31: ='05 Query-Key-Value'!$C$78 -> 0.5 | L31: ='05 Query-Key-Value'!$D$78 -> 0
B33: Q1 = X·W_Q1 | F33: K1 = X·W_K1 | J33: V1 = X·W_V1
C34: a | D34: b | G34: a | H34: b | K34: a | L34: b
B35: ='03 Embeddings'!$B$36 -> the | C35: =C20*C28+D20*C29+E20*C30+F20*C31 -> 1.2 | D35: =C20*D28+D20*D29+E20*D30+F20*D31 -> -0.4 | F35: ='03 Embeddings'!$B$36 -> the | G35: =C20*G28+D20*G29+E20*G30+F20*G31 -> 2 | H35: =C20*H28+D20*H29+E20*H30+F20*H31 -> 0.8 | J35: ='03 Embeddings'!$B$36 -> the | K35: =C20*K28+D20*K29+E20*K30+F20*K31 -> 1 | L35: =C20*L28+D20*L29+E20*L30+F20*L31 -> 0.6
B36: ='03 Embeddings'!$B$37 -> cat | C36: =C21*C28+D21*C29+E21*C30+F21*C31 -> 1.0514708 | D36: =C21*D28+D21*D29+E21*D30+F21*D31 -> 1.3403523 | F36: ='03 Embeddings'!$B$37 -> cat | G36: =C21*G28+D21*G29+E21*G30+F21*G31 -> 1.041421 | H36: =C21*H28+D21*H29+E21*H30+F21*H31 -> 2.9503021 | J36: ='03 Embeddings'!$B$37 -> cat | K36: =C21*K28+D21*K29+E21*K30+F21*K31 -> 0.52071049 | L36: =C21*L28+D21*L29+E21*L30+F21*L31 -> 2.1403023
B37: ='03 Embeddings'!$B$38 -> sat | C37: =C22*C28+D22*C29+E22*C30+F22*C31 -> 0.12929609 | D37: =C22*D28+D22*D29+E22*D30+F22*D31 -> -2.2159468 | F37: ='03 Embeddings'!$B$38 -> sat | G37: =C22*G28+D22*G29+E22*G30+F22*G31 -> 3.3090974 | H37: =C22*H28+D22*H29+E22*H30+F22*H31 -> -1.3961482 | J37: ='03 Embeddings'!$B$38 -> sat | K37: =C22*K28+D22*K29+E22*K30+F22*K31 -> 1.6545487 | L37: =C22*L28+D22*L29+E22*L30+F22*L31 -> -0.21614684
B39: Scores ÷ √d_k (head 1)
C40: ='03 Embeddings'!$B$36 -> the | D40: ='03 Embeddings'!$B$37 -> cat | E40: ='03 Embeddings'!$B$38 -> sat
B41: ='03 Embeddings'!$B$36 -> the | C41: =(C35*G35+D35*H35)/SQRT(C24) -> 1.4707821 | D41: =(C35*G36+D35*H36)/SQRT(C24) -> 0.049203549 | E41: =(C35*G37+D35*H37)/SQRT(C24) -> 3.2027526
B42: ='03 Embeddings'!$B$37 -> cat | C42: =(C36*G35+D36*H35)/SQRT(C24) -> 2.2452221 | D42: =(C36*G36+D36*H36)/SQRT(C24) -> 3.5705131 | E42: =(C36*G37+D36*H37)/SQRT(C24) -> 1.1370906
B43: ='03 Embeddings'!$B$38 -> sat | C43: =(C37*G35+D37*H35)/SQRT(C24) -> -1.0706765 | D43: =(C37*G36+D37*H36)/SQRT(C24) -> -4.5276479 | E43: =(C37*G37+D37*H37)/SQRT(C24) -> 2.490178
B45: exp(score) | H45: Head 1 weights
C46: ='03 Embeddings'!$B$36 -> the | D46: ='03 Embeddings'!$B$37 -> cat | E46: ='03 Embeddings'!$B$38 -> sat | F46: row total | I46: ='03 Embeddings'!$B$36 -> the | J46: ='03 Embeddings'!$B$37 -> cat | K46: ='03 Embeddings'!$B$38 -> sat
...

Sheet 09 Three Attentions
B1: 09 · The Three Uses of Attention in the Transformer
B2: Paper: §3.2.3 Applications of Attention in our Model
B4: BIG IDEA: The same attention machine is used in three places. What changes is only WHERE the queries, keys and values come from, and whether a mask is applied.
B5: Type | D5: Where | F5: Queries from | H5: Keys & values from | J5: Mask? | K5: Question it answers
B6: Encoder self-attention | D6: every encoder layer | F6: encoder (previous layer) | H6: encoder (same place) | J6: no | K6: 'Which input words help me understand this input word?'
B7: Masked decoder self-attention | D7: every decoder layer (1st sub-layer) | F7: decoder | H7: decoder | J7: yes (causal) | K7: 'Which of the words I've already written matter now?'
B8: Encoder–decoder (cross) attention | D8: every decoder layer (2nd sub-layer) | F8: decoder (previous layer) | H8: ENCODER OUTPUT (the 'memory') | J8: no | K8: 'Which input words should I translate right now?'
B9: §3.2.3: in encoder-decoder attention 'the queries come from the previous decoder layer, and the memory keys and values come from the output of the encoder. This allows every position in the decoder to attend over all positions in the input sequence.'
B10: ANALOGY: Encoder self-attention = students discussing the English text among themselves. Masked self-attention = the writer re-reading their own half-written German sentence. Cross-attention = the writer glancing back at the English original to decide the next word.
B12: Example 1 (simplest): cross-attention — the decoder is about to write 'Katze'
B13: Encoder memory for 'the cat sat' (2 numbers per word, made up). The decoder's current query comes from the German side. For simplicity we use the memory directly as keys AND values; in the real model each is first multiplied by its own W_K / W_V.
B14: Encoder memory (keys = values) | F14: Decoder query ('Katze' slot)
C15: m1 | D15: m2 | G15: m1 | H15: m2
B16: the | C16: 0 | D16: 1 | F16: query | G16: 2 | H16: 0
B17: cat | C17: 2 | D17: 0
B18: sat | C18: 1 | D18: 2
B20: d_k | C20: 2
B21: Score ÷ √d_k | E21: e^score | H21: Weight
C22: score | F22: e^s | I22: weight
B23: the | C23: =(G16*C16+H16*D16)/SQRT(C20) -> 0 | E23: the | F23: =EXP(C23) -> 1 | H23: the | I23: =F23/SUM(F23:F25) -> 0.045388363
B24: cat | C24: =(G16*C17+H16*D17)/SQRT(C20) -> 2.8284271 | E24: cat | F24: =EXP(C24) -> 16.918829 | H24: cat | I24: =F24/SUM(F23:F25) -> 0.76791794
B25: sat | C25: =(G16*C18+H16*D18)/SQRT(C20) -> 1.4142136 | E25: sat | F25: =EXP(C25) -> 4.1132504 | H25: sat | I25: =F25/SUM(F23:F25) -> 0.1866937
B27: score the | C27: ="(q·k) ÷ √d_k: "&IF(ROUND(G16,3)<0,"("&ROUND(G16,3)&")",ROUND(G16,3)&"")&"×"&IF(ROUND(C16,3)<0,"("&ROUND(C16,3)&")",ROUND(C16,3)&"")&" + "&IF(ROUND(H16,3)<0,"("&ROUND(H16,3)&")",ROUND(H16,3)&"")&"×"&IF(ROUND(D16,3)<0,"("&ROUND(D16,3)&")",ROUND(D16,3)&"")&" then ÷ √"&C20&" = "&IF(ROUND(C23,3)<0,"("&ROUND(C23,3)&")",ROUND(C23,3)&"") -> (q·k) ÷ √d_k: 2×0 + 0×1 then ÷ √2 = 0
B28: score cat | C28: ="(q·k) ÷ √d_k: "&IF(ROUND(G16,3)<0,"("&ROUND(G16,3)&")",ROUND(G16,3)&"")&"×"&IF(ROUND(C17,3)<0,"("&ROUND(C17,3)&")",ROUND(C17,3)&"")&" + "&IF(ROUND(H16,3)<0,"("&ROUND(H16,3)&")",ROUND(H16,3)&"")&"×"&IF(ROUND(D17,3)<0,"("&ROUND(D17,3)&")",ROUND(D17,3)&"")&" then ÷ √"&C20&" = "&IF(ROUND(C24,3)<0,"("&ROUND(C24,3)&")",ROUND(C24,3)&"") -> (q·k) ÷ √d_k: 2×2 + 0×0 then ÷ √2 = 2.828
B29: score sat | C29: ="(q·k) ÷ √d_k: "&IF(ROUND(G16,3)<0,"("&ROUND(G16,3)&")",ROUND(G16,3)&"")&"×"&IF(ROUND(C18,3)<0,"("&ROUND(C18,3)&")",ROUND(C18,3)&"")&" + "&IF(ROUND(H16,3)<0,"("&ROUND(H16,3)&")",ROUND(H16,3)&"")&"×"&IF(ROUND(D18,3)<0,"("&ROUND(D18,3)&")",ROUND(D18,3)&"")&" then ÷ √"&C20&" = "&IF(ROUND(C25,3)<0,"("&ROUND(C25,3)&")",ROUND(C25,3)&"") -> (q·k) ÷ √d_k: 2×1 + 0×2 then ÷ √2 = 1.414
B30: Context vector = Σ weight × memory
C31: m1 | D31: m2
C32: =I23*C16+I24*C17+I25*C18 -> 1.7225296 | D32: =I23*D16+I24*D17+I25*D18 -> 0.41877576
B34: The decoder 'looks' mostly at 'cat' — exactly the English word it should be translating into 'Katze'. In real models these cross-attention maps often look like a soft word-alignment between the two languages.
B36: Example 2 (moderate): shapes and counts in the full base model
B37: n = input length (words) | C37: 5
B38: m = output length so far | C38: 4
B39: N = layers per stack | C39: 6
B40: h = heads | C40: 8
B41: Attention type | F41: Score matrix shape | H41: Entries per head | J41: Blocks in the model | L41: Heads in the model
B42: Encoder self-attention | F42: =C37&" × "&C37 -> 5 × 5 | H42: =C37*C37 -> 25 | J42: =C39 -> 6 | L42: =C39*C40 -> 48
B43: Masked decoder self-attention | F43: =C38&" × "&C38 -> 4 × 4 | H43: =C38*C38 -> 16 | J43: =C39 -> 6 | L43: =C39*C40 -> 48
B44: Encoder–decoder attention | F44: =C38&" × "&C37 -> 4 × 5 | H44: =C38*C37 -> 20 | J44: =C39 -> 6 | L44: =C39*C40 -> 48
B45: TOTAL | J45: =3*C39 -> 18 | L45: =3*C39*C40 -> 144
B46: Note the cross-attention matrix is m × n — it need not be square, because the German and English sentences can have different lengths. The base model contains 18 attention blocks and 144 heads in total.
...

Sheet 10 Add and Norm
B1: 10 · Add & Norm — residual connections and layer normalisation
B2: Paper: §3.1 ('LayerNorm(x + Sublayer(x))'), references [11] residual learning and [1] layer normalization
B4: output of every sub-layer = LayerNorm( x + Sublayer(x) )
B5: BIG IDEA: Two stabilisers wrapped around EVERY attention and feed-forward block. ADD (residual): keep the input and add the sub-layer's correction on top. NORM: rescale each word's vector to mean 0 and spread 1, so numbers never drift out of control across 6 + 6 layers.
B6: ANALOGY: Residual = editing a document with 'track changes': you keep the original text and add edits on top, rather than rewriting it from scratch each time. LayerNorm = re-centring and re-scaling a photo's brightness after each edit so it never ends up all white or all black.
B7: 1. The LayerNorm formula
B8: LN(v) = γ ⊙ (v − μ) / √(σ² + ε) + β μ = mean of v's entries, σ² = their variance
B9: Symbol | C9: What it means in plain English | L9: Value in the paper
B10: v | C10: One word's vector (d_model numbers) | L10: 512 numbers
B11: μ, σ² | C11: Mean and variance across THAT word's own numbers (not across words or sentences) | L11: computed
B12: ε | C12: Tiny number to avoid dividing by zero; the paper doesn't state it — 1e-6 is common | L12: not stated
B13: γ, β | C13: Learned per-dimension scale and shift (start at 1 and 0) | L13: learned
B14: Example 1 (simplest): one word, d_model = 4
B15: x (sub-layer input)
C16: dim 1 | D16: dim 2 | E16: dim 3 | F16: dim 4
C17: 1 | D17: 2 | E17: 3 | F17: 4
B18: Sublayer(x) (e.g. attention output)
C19: dim 1 | D19: dim 2 | E19: dim 3 | F19: dim 4
C20: 0.5 | D20: -1 | E20: 0 | F20: 2.5
B21: ADD | C21: Residual: add input and sub-layer output element by element.
B22: v = x + Sublayer(x)
C23: dim 1 | D23: dim 2 | E23: dim 3 | F23: dim 4
C24: =C17+C20 -> 1.5 | D24: =D17+D20 -> 1 | E24: =E17+E20 -> 3 | F24: =F17+F20 -> 6.5
B25: NORM | C25: Compute this word's mean and variance, then standardise.
B26: mean μ | C26: =AVERAGE(C24:F24) -> 3
B27: variance σ² | C27: =SUMPRODUCT((C24:F24-C26)^2)/4 -> 4.625 | D27: average squared distance from μ (divide by 4)
B28: ε | C28: 1e-06 | D28: assumed (the paper does not specify)
B29: √(σ² + ε) | C29: =SQRT(C27+C28) -> 2.1505815
B30: Show the work | C30: ="μ = ("&IF(ROUND(C24,3)<0,"("&ROUND(C24,3)&")",ROUND(C24,3)&"")&" + "&IF(ROUND(D24,3)<0,"("&ROUND(D24,3)&")",ROUND(D24,3)&"")&" + "&IF(ROUND(E24,3)<0,"("&ROUND(E24,3)&")",ROUND(E24,3)&"")&" + "&IF(ROUND(F24,3)<0,"("&ROUND(F24,3)&")",ROUND(F24,3)&"")&") ÷ 4 = "&IF(ROUND(C26,3)<0,"("&ROUND(C26,3)&")",ROUND(C26,3)&"")&"; σ² = "&IF(ROUND(C27,3)<0,"("&ROUND(C27,3)&")",ROUND(C27,3)&"")&"; √(σ²+ε) = "&IF(ROUND(C29,3)<0,"("&ROUND(C29,3)&")",ROUND(C29,3)&"") -> μ = (1.5 + 1 + 3 + 6.5) ÷ 4 = 3; σ² = 4.625; √(σ²+ε) = 2.151
B31: (v − μ) ÷ √(σ²+ε)
C32: dim 1 | D32: dim 2 | E32: dim 3 | F32: dim 4
C33: =(C24-C26)/C29 -> -0.69748576 | D33: =(D24-C26)/C29 -> -0.92998101 | E33: =(E24-C26)/C29 -> 0 | F33: =(F24-C26)/C29 -> 1.6274668
B34: γ (scale)
C35: dim 1 | D35: dim 2 | E35: dim 3 | F35: dim 4
C36: 1 | D36: 1 | E36: 1 | F36: 1
B37: β (shift)
C38: dim 1 | D38: dim 2 | E38: dim 3 | F38: dim 4
C39: 0 | D39: 0 | E39: 0 | F39: 0
B40: LayerNorm output
C41: dim 1 | D41: dim 2 | E41: dim 3 | F41: dim 4
...

Sheet 11 Feed-Forward
B1: 11 · Position-wise Feed-Forward Network — each word 'thinks' on its own
B2: Paper: §3.3, Equation (2)
B4: FFN(x) = max(0, x·W₁ + b₁) · W₂ + b₂
B5: BIG IDEA: Attention lets words SHARE information. The feed-forward network then processes each word INDIVIDUALLY: expand its vector to 4× the size, switch off the negative parts (ReLU), and compress back. The same weights are used for every position.
B6: ANALOGY: After a group meeting (attention), everyone goes back to their own desk and works through what they heard, using the same method (same weights) — but each on their own notes.
B7: Symbol | C7: What it means in plain English | L7: Value in the paper
B8: x | C8: One word's vector (after Add & Norm) | L8: 512
B9: W₁, b₁ | C9: Expand: d_model → d_ff | L9: 512 × 2048, 2048
B10: max(0, ·) | C10: ReLU: negative numbers become 0 | L10: —
B11: W₂, b₂ | C11: Compress: d_ff → d_model | L11: 2048 × 512, 512
B12: position-wise | C12: Applied separately and identically to every word; 'two convolutions with kernel size 1' | L12: —
B13: Example 1 (simplest): d_model = 2, d_ff = 4 (the paper's 4× expansion ratio)
B14: x
C15: x1 | D15: x2
C16: 1 | D16: 2
B18: W₁ (2 × 4)
C19: h1 | D19: h2 | E19: h3 | F19: h4
B20: x1 | C20: 1 | D20: -1 | E20: 0.5 | F20: 2
B21: x2 | C21: 0 | D21: 1 | E21: -1 | F21: -0.5
B23: b₁
C24: h1 | D24: h2 | E24: h3 | F24: h4
C25: 0 | D25: 0.5 | E25: 0 | F25: -1
B27: Step 1 | C27: Expand: pre = x·W₁ + b₁ (4 numbers).
B28: pre-activation
C29: h1 | D29: h2 | E29: h3 | F29: h4
C30: =C16*C20+D16*C21+C25 -> 1 | D30: =C16*D20+D16*D21+D25 -> 1.5 | E30: =C16*E20+D16*E21+E25 -> -1.5 | F30: =C16*F20+D16*F21+F25 -> 0
B31: h1 | C31: =IF(ROUND(C16,3)<0,"("&ROUND(C16,3)&")",ROUND(C16,3)&"")&"×"&IF(ROUND(C20,3)<0,"("&ROUND(C20,3)&")",ROUND(C20,3)&"")&" + "&IF(ROUND(D16,3)<0,"("&ROUND(D16,3)&")",ROUND(D16,3)&"")&"×"&IF(ROUND(C21,3)<0,"("&ROUND(C21,3)&")",ROUND(C21,3)&"")&" + b₁ "&IF(ROUND(C25,3)<0,"("&ROUND(C25,3)&")",ROUND(C25,3)&"")&" = "&IF(ROUND(C30,3)<0,"("&ROUND(C30,3)&")",ROUND(C30,3)&"") -> 1×1 + 2×0 + b₁ 0 = 1
B32: h2 | C32: =IF(ROUND(C16,3)<0,"("&ROUND(C16,3)&")",ROUND(C16,3)&"")&"×"&IF(ROUND(D20,3)<0,"("&ROUND(D20,3)&")",ROUND(D20,3)&"")&" + "&IF(ROUND(D16,3)<0,"("&ROUND(D16,3)&")",ROUND(D16,3)&"")&"×"&IF(ROUND(D21,3)<0,"("&ROUND(D21,3)&")",ROUND(D21,3)&"")&" + b₁ "&IF(ROUND(D25,3)<0,"("&ROUND(D25,3)&")",ROUND(D25,3)&"")&" = "&IF(ROUND(D30,3)<0,"("&ROUND(D30,3)&")",ROUND(D30,3)&"") -> 1×(-1) + 2×1 + b₁ 0.5 = 1.5
B33: h3 | C33: =IF(ROUND(C16,3)<0,"("&ROUND(C16,3)&")",ROUND(C16,3)&"")&"×"&IF(ROUND(E20,3)<0,"("&ROUND(E20,3)&")",ROUND(E20,3)&"")&" + "&IF(ROUND(D16,3)<0,"("&ROUND(D16,3)&")",ROUND(D16,3)&"")&"×"&IF(ROUND(E21,3)<0,"("&ROUND(E21,3)&")",ROUND(E21,3)&"")&" + b₁ "&IF(ROUND(E25,3)<0,"("&ROUND(E25,3)&")",ROUND(E25,3)&"")&" = "&IF(ROUND(E30,3)<0,"("&ROUND(E30,3)&")",ROUND(E30,3)&"") -> 1×0.5 + 2×(-1) + b₁ 0 = (-1.5)
B34: h4 | C34: =IF(ROUND(C16,3)<0,"("&ROUND(C16,3)&")",ROUND(C16,3)&"")&"×"&IF(ROUND(F20,3)<0,"("&ROUND(F20,3)&")",ROUND(F20,3)&"")&" + "&IF(ROUND(D16,3)<0,"("&ROUND(D16,3)&")",ROUND(D16,3)&"")&"×"&IF(ROUND(F21,3)<0,"("&ROUND(F21,3)&")",ROUND(F21,3)&"")&" + b₁ "&IF(ROUND(F25,3)<0,"("&ROUND(F25,3)&")",ROUND(F25,3)&"")&" = "&IF(ROUND(F30,3)<0,"("&ROUND(F30,3)&")",ROUND(F30,3)&"") -> 1×2 + 2×(-0.5) + b₁ (-1) = 0
B35: Step 2 | C35: ReLU: keep positives, zero out negatives.
B36: hidden = max(0, pre)
C37: h1 | D37: h2 | E37: h3 | F37: h4
C38: =MAX(0,C30) -> 1 | D38: =MAX(0,D30) -> 1.5 | E38: =MAX(0,E30) -> 0 | F38: =MAX(0,F30) -> 0
B39: Step 3 | C39: Compress: out = hidden·W₂ + b₂ (back to 2 numbers).
B40: W₂ (4 × 2) | F40: b₂
C41: o1 | D41: o2 | G41: o1 | H41: o2
B42: h1 | C42: 1 | D42: 0 | G42: 0.1 | H42: -0.1
B43: h2 | C43: 0 | D43: 1
B44: h3 | C44: 3 | D44: 3
...

Sheet 12 Output and Decoding
B1: 12 · From Vectors Back to Words — the output layer, softmax and beam search
B2: Paper: §3.4 (shared weights, pre-softmax linear transformation), §6.1 (beam size 4, length penalty α = 0.6)
B4: BIG IDEA: The decoder's final vector for a position is compared (dot product) with EVERY token's embedding. The best matches get the highest scores ('logits'); softmax turns the logits into next-word probabilities. Then a search strategy picks the actual words.
B5: P(next token) = softmax( h · Eᵀ ) h = decoder's final vector, E = the shared embedding table
B6: Because the same table E is used for input embeddings and here, 'is this output vector similar to the embedding of Katze?' is literally the question being asked (§3.4: 'we share the same weight matrix between the two embedding layers and the pre-softmax linear transformation').
B7: Example 1 (simplest): scoring our 8-token vocabulary
